[2023-11-21T19:26:04.919+0000] {taskinstance.py:1159} INFO - Dependencies all met for dep_context=non-requeueable deps ti=<TaskInstance: Projet_IDD.load_data manual__2023-11-21T19:26:01.125517+00:00 [queued]>
[2023-11-21T19:26:04.930+0000] {taskinstance.py:1159} INFO - Dependencies all met for dep_context=requeueable deps ti=<TaskInstance: Projet_IDD.load_data manual__2023-11-21T19:26:01.125517+00:00 [queued]>
[2023-11-21T19:26:04.931+0000] {taskinstance.py:1361} INFO - Starting attempt 1 of 1
[2023-11-21T19:26:04.945+0000] {taskinstance.py:1382} INFO - Executing <Task(PythonOperator): load_data> on 2023-11-21 19:26:01.125517+00:00
[2023-11-21T19:26:04.950+0000] {standard_task_runner.py:57} INFO - Started process 2372 to run task
[2023-11-21T19:26:04.954+0000] {standard_task_runner.py:84} INFO - Running: ['***', 'tasks', 'run', 'Projet_IDD', 'load_data', 'manual__2023-11-21T19:26:01.125517+00:00', '--job-id', '64', '--raw', '--subdir', 'DAGS_FOLDER/ETL.py', '--cfg-path', '/tmp/tmp5c2eau35']
[2023-11-21T19:26:04.958+0000] {standard_task_runner.py:85} INFO - Job 64: Subtask load_data
[2023-11-21T19:26:05.037+0000] {task_command.py:416} INFO - Running <TaskInstance: Projet_IDD.load_data manual__2023-11-21T19:26:01.125517+00:00 [running]> on host 726cce66553f
[2023-11-21T19:26:05.333+0000] {taskinstance.py:1662} INFO - Exporting env vars: AIRFLOW_CTX_DAG_OWNER='***' AIRFLOW_CTX_DAG_ID='Projet_IDD' AIRFLOW_CTX_TASK_ID='load_data' AIRFLOW_CTX_EXECUTION_DATE='2023-11-21T19:26:01.125517+00:00' AIRFLOW_CTX_TRY_NUMBER='1' AIRFLOW_CTX_DAG_RUN_ID='manual__2023-11-21T19:26:01.125517+00:00'
[2023-11-21T19:26:05.469+0000] {base.py:73} INFO - Using connection ID 'postgres_connexion' for task execution.
[2023-11-21T19:26:05.521+0000] {taskinstance.py:1937} ERROR - Task failed with exception
Traceback (most recent call last):
  File "/home/airflow/.local/lib/python3.8/site-packages/sqlalchemy/engine/base.py", line 1890, in _execute_context
    self.dialect.do_executemany(
  File "/home/airflow/.local/lib/python3.8/site-packages/sqlalchemy/dialects/postgresql/psycopg2.py", line 982, in do_executemany
    context._psycopg2_fetched_rows = xtras.execute_values(
  File "/home/airflow/.local/lib/python3.8/site-packages/psycopg2/extras.py", line 1299, in execute_values
    cur.execute(b''.join(parts))
psycopg2.errors.UndefinedColumn: column "Code tranches" of relation "departements" does not exist
LINE 1: INSERT INTO departements ("Code tranches", age) VALUES (0, '...
                                  ^


The above exception was the direct cause of the following exception:

Traceback (most recent call last):
  File "/home/airflow/.local/lib/python3.8/site-packages/airflow/operators/python.py", line 192, in execute
    return_value = self.execute_callable()
  File "/home/airflow/.local/lib/python3.8/site-packages/airflow/operators/python.py", line 209, in execute_callable
    return self.python_callable(*self.op_args, **self.op_kwargs)
  File "/opt/airflow/dags/ETL.py", line 55, in load_data
    df_departements.to_sql('departements', postgres_sql_upload.get_sqlalchemy_engine(), if_exists='append', index=False)
  File "/home/airflow/.local/lib/python3.8/site-packages/pandas/core/generic.py", line 2878, in to_sql
    return sql.to_sql(
  File "/home/airflow/.local/lib/python3.8/site-packages/pandas/io/sql.py", line 769, in to_sql
    return pandas_sql.to_sql(
  File "/home/airflow/.local/lib/python3.8/site-packages/pandas/io/sql.py", line 1920, in to_sql
    total_inserted = sql_engine.insert_records(
  File "/home/airflow/.local/lib/python3.8/site-packages/pandas/io/sql.py", line 1470, in insert_records
    raise err
  File "/home/airflow/.local/lib/python3.8/site-packages/pandas/io/sql.py", line 1461, in insert_records
    return table.insert(chunksize=chunksize, method=method)
  File "/home/airflow/.local/lib/python3.8/site-packages/pandas/io/sql.py", line 1023, in insert
    num_inserted = exec_insert(conn, keys, chunk_iter)
  File "/home/airflow/.local/lib/python3.8/site-packages/pandas/io/sql.py", line 929, in _execute_insert
    result = conn.execute(self.table.insert(), data)
  File "/home/airflow/.local/lib/python3.8/site-packages/sqlalchemy/engine/base.py", line 1385, in execute
    return meth(self, multiparams, params, _EMPTY_EXECUTION_OPTS)
  File "/home/airflow/.local/lib/python3.8/site-packages/sqlalchemy/sql/elements.py", line 334, in _execute_on_connection
    return connection._execute_clauseelement(
  File "/home/airflow/.local/lib/python3.8/site-packages/sqlalchemy/engine/base.py", line 1577, in _execute_clauseelement
    ret = self._execute_context(
  File "/home/airflow/.local/lib/python3.8/site-packages/sqlalchemy/engine/base.py", line 1953, in _execute_context
    self._handle_dbapi_exception(
  File "/home/airflow/.local/lib/python3.8/site-packages/sqlalchemy/engine/base.py", line 2134, in _handle_dbapi_exception
    util.raise_(
  File "/home/airflow/.local/lib/python3.8/site-packages/sqlalchemy/util/compat.py", line 211, in raise_
    raise exception
  File "/home/airflow/.local/lib/python3.8/site-packages/sqlalchemy/engine/base.py", line 1890, in _execute_context
    self.dialect.do_executemany(
  File "/home/airflow/.local/lib/python3.8/site-packages/sqlalchemy/dialects/postgresql/psycopg2.py", line 982, in do_executemany
    context._psycopg2_fetched_rows = xtras.execute_values(
  File "/home/airflow/.local/lib/python3.8/site-packages/psycopg2/extras.py", line 1299, in execute_values
    cur.execute(b''.join(parts))
sqlalchemy.exc.ProgrammingError: (psycopg2.errors.UndefinedColumn) column "Code tranches" of relation "departements" does not exist
LINE 1: INSERT INTO departements ("Code tranches", age) VALUES (0, '...
                                  ^

[SQL: INSERT INTO departements ("Code tranches", age) VALUES (%(Code_tranches)s, %(age)s)]
[parameters: ({'Code_tranches': 0, 'age': 'tous ages'}, {'Code_tranches': 1, 'age': '0-4 ans'}, {'Code_tranches': 2, 'age': '5-14 ans'}, {'Code_tranches': 3, 'age': '15-44 ans'}, {'Code_tranches': 4, 'age': '45-64 ans'}, {'Code_tranches': 5, 'age': '65-74 ans'}, {'Code_tranches': 6, 'age': '75 et plus'})]
(Background on this error at: https://sqlalche.me/e/14/f405)
[2023-11-21T19:26:05.538+0000] {taskinstance.py:1400} INFO - Marking task as FAILED. dag_id=Projet_IDD, task_id=load_data, execution_date=20231121T192601, start_date=20231121T192604, end_date=20231121T192605
[2023-11-21T19:26:05.551+0000] {standard_task_runner.py:104} ERROR - Failed to execute job 64 for task load_data ((psycopg2.errors.UndefinedColumn) column "Code tranches" of relation "departements" does not exist
LINE 1: INSERT INTO departements ("Code tranches", age) VALUES (0, '...
                                  ^

[SQL: INSERT INTO departements ("Code tranches", age) VALUES (%(Code_tranches)s, %(age)s)]
[parameters: ({'Code_tranches': 0, 'age': 'tous ages'}, {'Code_tranches': 1, 'age': '0-4 ans'}, {'Code_tranches': 2, 'age': '5-14 ans'}, {'Code_tranches': 3, 'age': '15-44 ans'}, {'Code_tranches': 4, 'age': '45-64 ans'}, {'Code_tranches': 5, 'age': '65-74 ans'}, {'Code_tranches': 6, 'age': '75 et plus'})]
(Background on this error at: https://sqlalche.me/e/14/f405); 2372)
[2023-11-21T19:26:05.569+0000] {local_task_job_runner.py:228} INFO - Task exited with return code 1
[2023-11-21T19:26:05.585+0000] {taskinstance.py:2778} INFO - 0 downstream tasks scheduled from follow-on schedule check
