[2023-11-24T15:28:17.026+0000] {taskinstance.py:1159} INFO - Dependencies all met for dep_context=non-requeueable deps ti=<TaskInstance: Projet_IDD.extract_and_transform_laod manual__2023-11-24T15:28:14.216887+00:00 [queued]>
[2023-11-24T15:28:17.034+0000] {taskinstance.py:1159} INFO - Dependencies all met for dep_context=requeueable deps ti=<TaskInstance: Projet_IDD.extract_and_transform_laod manual__2023-11-24T15:28:14.216887+00:00 [queued]>
[2023-11-24T15:28:17.036+0000] {taskinstance.py:1361} INFO - Starting attempt 1 of 1
[2023-11-24T15:28:17.049+0000] {taskinstance.py:1382} INFO - Executing <Task(PythonOperator): extract_and_transform_laod> on 2023-11-24 15:28:14.216887+00:00
[2023-11-24T15:28:17.053+0000] {standard_task_runner.py:57} INFO - Started process 801 to run task
[2023-11-24T15:28:17.056+0000] {standard_task_runner.py:84} INFO - Running: ['***', 'tasks', 'run', 'Projet_IDD', 'extract_and_transform_laod', 'manual__2023-11-24T15:28:14.216887+00:00', '--job-id', '24', '--raw', '--subdir', 'DAGS_FOLDER/ETL.py', '--cfg-path', '/tmp/tmp8fm123zi']
[2023-11-24T15:28:17.060+0000] {standard_task_runner.py:85} INFO - Job 24: Subtask extract_and_transform_laod
[2023-11-24T15:28:17.104+0000] {task_command.py:416} INFO - Running <TaskInstance: Projet_IDD.extract_and_transform_laod manual__2023-11-24T15:28:14.216887+00:00 [running]> on host 1697b77d64fd
[2023-11-24T15:28:17.316+0000] {taskinstance.py:1662} INFO - Exporting env vars: AIRFLOW_CTX_DAG_OWNER='***' AIRFLOW_CTX_DAG_ID='Projet_IDD' AIRFLOW_CTX_TASK_ID='extract_and_transform_laod' AIRFLOW_CTX_EXECUTION_DATE='2023-11-24T15:28:14.216887+00:00' AIRFLOW_CTX_TRY_NUMBER='1' AIRFLOW_CTX_DAG_RUN_ID='manual__2023-11-24T15:28:14.216887+00:00'
[2023-11-24T15:28:17.497+0000] {logging_mixin.py:151} INFO -   Code tranches         age
0             0   tous ages
1             A     0-4 ans
2             B    5-14 ans
3             C   15-44 ans
4             D   45-64 ans
5             E   65-74 ans
6             F  75 et plus
[2023-11-24T15:28:17.563+0000] {logging_mixin.py:151} INFO -         dep date_de_passage  ...  nbre_hospit_corona_h  nbre_hospit_corona_f
0        01      2022-12-26  ...                   1.0                   3.0
1        01      2022-12-26  ...                   NaN                   NaN
2        01      2022-12-26  ...                   NaN                   NaN
3        01      2022-12-26  ...                   NaN                   NaN
4        01      2022-12-26  ...                   NaN                   NaN
...     ...             ...  ...                   ...                   ...
214215  976      2023-10-24  ...                   NaN                   NaN
214216  976      2023-10-24  ...                   NaN                   NaN
214217  976      2023-10-24  ...                   NaN                   NaN
214218  976      2023-10-24  ...                   NaN                   NaN
214219  976      2023-10-24  ...                   NaN                   NaN

[212928 rows x 12 columns]
[2023-11-24T15:28:17.580+0000] {logging_mixin.py:151} INFO -         dep date_de_passage  ... nbre_hospit_corona_h  nbre_hospit_corona_f
0        01      2022-12-26  ...                  1.0                   3.0
1        01      2022-12-26  ...                  NaN                   NaN
2        01      2022-12-26  ...                  NaN                   NaN
3        01      2022-12-26  ...                  NaN                   NaN
4        01      2022-12-26  ...                  NaN                   NaN
...     ...             ...  ...                  ...                   ...
214215  976      2023-10-24  ...                  NaN                   NaN
214216  976      2023-10-24  ...                  NaN                   NaN
214217  976      2023-10-24  ...                  NaN                   NaN
214218  976      2023-10-24  ...                  NaN                   NaN
214219  976      2023-10-24  ...                  NaN                   NaN

[212928 rows x 12 columns]
[2023-11-24T15:28:17.582+0000] {logging_mixin.py:151} INFO - 0       01
1       02
2       03
3       04
4       05
      ... 
96     971
97     972
98     973
99     974
100    976
Name: num_dep, Length: 101, dtype: object
[2023-11-24T15:28:17.629+0000] {base.py:73} INFO - Using connection ID 'postgres_connexion' for task execution.
[2023-11-24T15:28:23.989+0000] {base.py:73} INFO - Using connection ID 'postgres_connexion' for task execution.
[2023-11-24T15:28:24.074+0000] {base.py:73} INFO - Using connection ID 'postgres_connexion' for task execution.
[2023-11-24T15:28:24.127+0000] {taskinstance.py:1937} ERROR - Task failed with exception
Traceback (most recent call last):
  File "/home/airflow/.local/lib/python3.8/site-packages/sqlalchemy/engine/base.py", line 1890, in _execute_context
    self.dialect.do_executemany(
  File "/home/airflow/.local/lib/python3.8/site-packages/sqlalchemy/dialects/postgresql/psycopg2.py", line 982, in do_executemany
    context._psycopg2_fetched_rows = xtras.execute_values(
  File "/home/airflow/.local/lib/python3.8/site-packages/psycopg2/extras.py", line 1299, in execute_values
    cur.execute(b''.join(parts))
psycopg2.errors.UniqueViolation: duplicate key value violates unique constraint "hospitalisation_pkey"
DETAIL:  Key (num_dep, date_pass)=(01, 2022-12-26) already exists.


The above exception was the direct cause of the following exception:

Traceback (most recent call last):
  File "/home/airflow/.local/lib/python3.8/site-packages/airflow/operators/python.py", line 192, in execute
    return_value = self.execute_callable()
  File "/home/airflow/.local/lib/python3.8/site-packages/airflow/operators/python.py", line 209, in execute_callable
    return self.python_callable(*self.op_args, **self.op_kwargs)
  File "/opt/airflow/dags/ETL.py", line 72, in extract_and_transform_laod
    df_hospitalisation.to_sql('hospitalisation', postgres_sql_upload.get_sqlalchemy_engine(), if_exists='append', chunksize=1000,index=False)
  File "/home/airflow/.local/lib/python3.8/site-packages/pandas/core/generic.py", line 2878, in to_sql
    return sql.to_sql(
  File "/home/airflow/.local/lib/python3.8/site-packages/pandas/io/sql.py", line 769, in to_sql
    return pandas_sql.to_sql(
  File "/home/airflow/.local/lib/python3.8/site-packages/pandas/io/sql.py", line 1920, in to_sql
    total_inserted = sql_engine.insert_records(
  File "/home/airflow/.local/lib/python3.8/site-packages/pandas/io/sql.py", line 1470, in insert_records
    raise err
  File "/home/airflow/.local/lib/python3.8/site-packages/pandas/io/sql.py", line 1461, in insert_records
    return table.insert(chunksize=chunksize, method=method)
  File "/home/airflow/.local/lib/python3.8/site-packages/pandas/io/sql.py", line 1023, in insert
    num_inserted = exec_insert(conn, keys, chunk_iter)
  File "/home/airflow/.local/lib/python3.8/site-packages/pandas/io/sql.py", line 929, in _execute_insert
    result = conn.execute(self.table.insert(), data)
  File "/home/airflow/.local/lib/python3.8/site-packages/sqlalchemy/engine/base.py", line 1385, in execute
    return meth(self, multiparams, params, _EMPTY_EXECUTION_OPTS)
  File "/home/airflow/.local/lib/python3.8/site-packages/sqlalchemy/sql/elements.py", line 334, in _execute_on_connection
    return connection._execute_clauseelement(
  File "/home/airflow/.local/lib/python3.8/site-packages/sqlalchemy/engine/base.py", line 1577, in _execute_clauseelement
    ret = self._execute_context(
  File "/home/airflow/.local/lib/python3.8/site-packages/sqlalchemy/engine/base.py", line 1953, in _execute_context
    self._handle_dbapi_exception(
  File "/home/airflow/.local/lib/python3.8/site-packages/sqlalchemy/engine/base.py", line 2134, in _handle_dbapi_exception
    util.raise_(
  File "/home/airflow/.local/lib/python3.8/site-packages/sqlalchemy/util/compat.py", line 211, in raise_
    raise exception
  File "/home/airflow/.local/lib/python3.8/site-packages/sqlalchemy/engine/base.py", line 1890, in _execute_context
    self.dialect.do_executemany(
  File "/home/airflow/.local/lib/python3.8/site-packages/sqlalchemy/dialects/postgresql/psycopg2.py", line 982, in do_executemany
    context._psycopg2_fetched_rows = xtras.execute_values(
  File "/home/airflow/.local/lib/python3.8/site-packages/psycopg2/extras.py", line 1299, in execute_values
    cur.execute(b''.join(parts))
sqlalchemy.exc.IntegrityError: (psycopg2.errors.UniqueViolation) duplicate key value violates unique constraint "hospitalisation_pkey"
DETAIL:  Key (num_dep, date_pass)=(01, 2022-12-26) already exists.

[SQL: INSERT INTO hospitalisation (date_pass, num_dep) VALUES (%(date_pass)s, %(num_dep)s)]
[parameters: ({'date_pass': datetime.datetime(2022, 12, 26, 0, 0), 'num_dep': '01'}, {'date_pass': datetime.datetime(2022, 12, 27, 0, 0), 'num_dep': '01'}, {'date_pass': datetime.datetime(2022, 12, 28, 0, 0), 'num_dep': '01'}, {'date_pass': datetime.datetime(2022, 12, 29, 0, 0), 'num_dep': '01'}, {'date_pass': datetime.datetime(2022, 12, 30, 0, 0), 'num_dep': '01'}, {'date_pass': datetime.datetime(2022, 12, 31, 0, 0), 'num_dep': '01'}, {'date_pass': datetime.datetime(2023, 1, 1, 0, 0), 'num_dep': '01'}, {'date_pass': datetime.datetime(2023, 1, 2, 0, 0), 'num_dep': '01'}  ... displaying 10 of 1000 total bound parameter sets ...  {'date_pass': datetime.datetime(2023, 3, 25, 0, 0), 'num_dep': '04'}, {'date_pass': datetime.datetime(2023, 3, 26, 0, 0), 'num_dep': '04'})]
(Background on this error at: https://sqlalche.me/e/14/gkpj)
[2023-11-24T15:28:24.141+0000] {taskinstance.py:1400} INFO - Marking task as FAILED. dag_id=Projet_IDD, task_id=extract_and_transform_laod, execution_date=20231124T152814, start_date=20231124T152817, end_date=20231124T152824
[2023-11-24T15:28:24.154+0000] {standard_task_runner.py:104} ERROR - Failed to execute job 24 for task extract_and_transform_laod ((psycopg2.errors.UniqueViolation) duplicate key value violates unique constraint "hospitalisation_pkey"
DETAIL:  Key (num_dep, date_pass)=(01, 2022-12-26) already exists.

[SQL: INSERT INTO hospitalisation (date_pass, num_dep) VALUES (%(date_pass)s, %(num_dep)s)]
[parameters: ({'date_pass': datetime.datetime(2022, 12, 26, 0, 0), 'num_dep': '01'}, {'date_pass': datetime.datetime(2022, 12, 27, 0, 0), 'num_dep': '01'}, {'date_pass': datetime.datetime(2022, 12, 28, 0, 0), 'num_dep': '01'}, {'date_pass': datetime.datetime(2022, 12, 29, 0, 0), 'num_dep': '01'}, {'date_pass': datetime.datetime(2022, 12, 30, 0, 0), 'num_dep': '01'}, {'date_pass': datetime.datetime(2022, 12, 31, 0, 0), 'num_dep': '01'}, {'date_pass': datetime.datetime(2023, 1, 1, 0, 0), 'num_dep': '01'}, {'date_pass': datetime.datetime(2023, 1, 2, 0, 0), 'num_dep': '01'}  ... displaying 10 of 1000 total bound parameter sets ...  {'date_pass': datetime.datetime(2023, 3, 25, 0, 0), 'num_dep': '04'}, {'date_pass': datetime.datetime(2023, 3, 26, 0, 0), 'num_dep': '04'})]
(Background on this error at: https://sqlalche.me/e/14/gkpj); 801)
[2023-11-24T15:28:24.169+0000] {local_task_job_runner.py:228} INFO - Task exited with return code 1
[2023-11-24T15:28:24.187+0000] {taskinstance.py:2778} INFO - 0 downstream tasks scheduled from follow-on schedule check
