[2023-11-21T18:16:32.652+0000] {taskinstance.py:1159} INFO - Dependencies all met for dep_context=non-requeueable deps ti=<TaskInstance: Projet_IDD.extract_data manual__2023-11-21T18:16:15.996256+00:00 [queued]>
[2023-11-21T18:16:32.667+0000] {taskinstance.py:1159} INFO - Dependencies all met for dep_context=requeueable deps ti=<TaskInstance: Projet_IDD.extract_data manual__2023-11-21T18:16:15.996256+00:00 [queued]>
[2023-11-21T18:16:32.668+0000] {taskinstance.py:1361} INFO - Starting attempt 1 of 1
[2023-11-21T18:16:32.685+0000] {taskinstance.py:1382} INFO - Executing <Task(PythonOperator): extract_data> on 2023-11-21 18:16:15.996256+00:00
[2023-11-21T18:16:32.694+0000] {standard_task_runner.py:57} INFO - Started process 1247 to run task
[2023-11-21T18:16:32.698+0000] {standard_task_runner.py:84} INFO - Running: ['***', 'tasks', 'run', 'Projet_IDD', 'extract_data', 'manual__2023-11-21T18:16:15.996256+00:00', '--job-id', '20', '--raw', '--subdir', 'DAGS_FOLDER/ETL.py', '--cfg-path', '/tmp/tmpdkyxit41']
[2023-11-21T18:16:32.701+0000] {standard_task_runner.py:85} INFO - Job 20: Subtask extract_data
[2023-11-21T18:16:32.768+0000] {task_command.py:416} INFO - Running <TaskInstance: Projet_IDD.extract_data manual__2023-11-21T18:16:15.996256+00:00 [running]> on host 726cce66553f
[2023-11-21T18:16:33.245+0000] {taskinstance.py:1662} INFO - Exporting env vars: AIRFLOW_CTX_DAG_OWNER='***' AIRFLOW_CTX_DAG_ID='Projet_IDD' AIRFLOW_CTX_TASK_ID='extract_data' AIRFLOW_CTX_EXECUTION_DATE='2023-11-21T18:16:15.996256+00:00' AIRFLOW_CTX_TRY_NUMBER='1' AIRFLOW_CTX_DAG_RUN_ID='manual__2023-11-21T18:16:15.996256+00:00'
[2023-11-21T18:16:34.611+0000] {logging_mixin.py:151} INFO -   Code tranches;age
0       0;tous ages
1         A;0-4 ans
2        B;5-14 ans
3       C;15-44 ans
4       D;45-64 ans
5       E;65-74 ans
6      F;75 et plus
[2023-11-21T18:16:34.713+0000] {taskinstance.py:1937} ERROR - Task failed with exception
Traceback (most recent call last):
  File "/home/airflow/.local/lib/python3.8/site-packages/pandas/core/indexes/base.py", line 3653, in get_loc
    return self._engine.get_loc(casted_key)
  File "pandas/_libs/index.pyx", line 147, in pandas._libs.index.IndexEngine.get_loc
  File "pandas/_libs/index.pyx", line 176, in pandas._libs.index.IndexEngine.get_loc
  File "pandas/_libs/hashtable_class_helper.pxi", line 7080, in pandas._libs.hashtable.PyObjectHashTable.get_item
  File "pandas/_libs/hashtable_class_helper.pxi", line 7088, in pandas._libs.hashtable.PyObjectHashTable.get_item
KeyError: 'Code tranches'

The above exception was the direct cause of the following exception:

Traceback (most recent call last):
  File "/home/airflow/.local/lib/python3.8/site-packages/airflow/operators/python.py", line 192, in execute
    return_value = self.execute_callable()
  File "/home/airflow/.local/lib/python3.8/site-packages/airflow/operators/python.py", line 209, in execute_callable
    return self.python_callable(*self.op_args, **self.op_kwargs)
  File "/opt/airflow/dags/ETL.py", line 36, in extract_data
    df_tranches_dage['Code tranches'] = df_tranches_dage['Code tranches'].replace({'A': 1, 'B': 2, 'C': 3, 'D': 4, 'E': 5, 'F': 6})
  File "/home/airflow/.local/lib/python3.8/site-packages/pandas/core/frame.py", line 3761, in __getitem__
    indexer = self.columns.get_loc(key)
  File "/home/airflow/.local/lib/python3.8/site-packages/pandas/core/indexes/base.py", line 3655, in get_loc
    raise KeyError(key) from err
KeyError: 'Code tranches'
[2023-11-21T18:16:34.740+0000] {taskinstance.py:1400} INFO - Marking task as FAILED. dag_id=Projet_IDD, task_id=extract_data, execution_date=20231121T181615, start_date=20231121T181632, end_date=20231121T181634
[2023-11-21T18:16:34.760+0000] {standard_task_runner.py:104} ERROR - Failed to execute job 20 for task extract_data ('Code tranches'; 1247)
[2023-11-21T18:16:34.804+0000] {local_task_job_runner.py:228} INFO - Task exited with return code 1
[2023-11-21T18:16:34.833+0000] {taskinstance.py:2778} INFO - 0 downstream tasks scheduled from follow-on schedule check
