[2023-11-21T18:22:41.285+0000] {taskinstance.py:1159} INFO - Dependencies all met for dep_context=non-requeueable deps ti=<TaskInstance: Projet_IDD.transform_and_load manual__2023-11-21T18:22:36.824169+00:00 [queued]>
[2023-11-21T18:22:41.295+0000] {taskinstance.py:1159} INFO - Dependencies all met for dep_context=requeueable deps ti=<TaskInstance: Projet_IDD.transform_and_load manual__2023-11-21T18:22:36.824169+00:00 [queued]>
[2023-11-21T18:22:41.296+0000] {taskinstance.py:1361} INFO - Starting attempt 1 of 1
[2023-11-21T18:22:41.311+0000] {taskinstance.py:1382} INFO - Executing <Task(PythonOperator): transform_and_load> on 2023-11-21 18:22:36.824169+00:00
[2023-11-21T18:22:41.317+0000] {standard_task_runner.py:57} INFO - Started process 1365 to run task
[2023-11-21T18:22:41.320+0000] {standard_task_runner.py:84} INFO - Running: ['***', 'tasks', 'run', 'Projet_IDD', 'transform_and_load', 'manual__2023-11-21T18:22:36.824169+00:00', '--job-id', '25', '--raw', '--subdir', 'DAGS_FOLDER/ETL.py', '--cfg-path', '/tmp/tmprop12asq']
[2023-11-21T18:22:41.323+0000] {standard_task_runner.py:85} INFO - Job 25: Subtask transform_and_load
[2023-11-21T18:22:41.370+0000] {task_command.py:416} INFO - Running <TaskInstance: Projet_IDD.transform_and_load manual__2023-11-21T18:22:36.824169+00:00 [running]> on host 726cce66553f
[2023-11-21T18:22:41.595+0000] {taskinstance.py:1662} INFO - Exporting env vars: AIRFLOW_CTX_DAG_OWNER='***' AIRFLOW_CTX_DAG_ID='Projet_IDD' AIRFLOW_CTX_TASK_ID='transform_and_load' AIRFLOW_CTX_EXECUTION_DATE='2023-11-21T18:22:36.824169+00:00' AIRFLOW_CTX_TRY_NUMBER='1' AIRFLOW_CTX_DAG_RUN_ID='manual__2023-11-21T18:22:36.824169+00:00'
[2023-11-21T18:22:41.808+0000] {taskinstance.py:1937} ERROR - Task failed with exception
Traceback (most recent call last):
  File "/home/airflow/.local/lib/python3.8/site-packages/airflow/operators/python.py", line 192, in execute
    return_value = self.execute_callable()
  File "/home/airflow/.local/lib/python3.8/site-packages/airflow/operators/python.py", line 209, in execute_callable
    return self.python_callable(*self.op_args, **self.op_kwargs)
  File "/opt/airflow/dags/ETL.py", line 54, in transform_and_load
    df_urgences = df_urgences.dropna(subset=['nbre_pass_tot'])
  File "/home/airflow/.local/lib/python3.8/site-packages/pandas/core/frame.py", line 6407, in dropna
    raise KeyError(np.array(subset)[check].tolist())
KeyError: ['nbre_pass_tot']
[2023-11-21T18:22:41.827+0000] {taskinstance.py:1400} INFO - Marking task as FAILED. dag_id=Projet_IDD, task_id=transform_and_load, execution_date=20231121T182236, start_date=20231121T182241, end_date=20231121T182241
[2023-11-21T18:22:41.842+0000] {standard_task_runner.py:104} ERROR - Failed to execute job 25 for task transform_and_load (['nbre_pass_tot']; 1365)
[2023-11-21T18:22:41.856+0000] {local_task_job_runner.py:228} INFO - Task exited with return code 1
[2023-11-21T18:22:41.881+0000] {taskinstance.py:2778} INFO - 0 downstream tasks scheduled from follow-on schedule check
