[2023-11-24T14:37:30.839+0000] {taskinstance.py:1159} INFO - Dependencies all met for dep_context=non-requeueable deps ti=<TaskInstance: Projet_IDD.extract_and_transform_laod manual__2023-11-24T14:37:27.903328+00:00 [queued]>
[2023-11-24T14:37:30.848+0000] {taskinstance.py:1159} INFO - Dependencies all met for dep_context=requeueable deps ti=<TaskInstance: Projet_IDD.extract_and_transform_laod manual__2023-11-24T14:37:27.903328+00:00 [queued]>
[2023-11-24T14:37:30.850+0000] {taskinstance.py:1361} INFO - Starting attempt 1 of 1
[2023-11-24T14:37:30.863+0000] {taskinstance.py:1382} INFO - Executing <Task(PythonOperator): extract_and_transform_laod> on 2023-11-24 14:37:27.903328+00:00
[2023-11-24T14:37:30.869+0000] {standard_task_runner.py:57} INFO - Started process 1721 to run task
[2023-11-24T14:37:30.872+0000] {standard_task_runner.py:84} INFO - Running: ['***', 'tasks', 'run', 'Projet_IDD', 'extract_and_transform_laod', 'manual__2023-11-24T14:37:27.903328+00:00', '--job-id', '55', '--raw', '--subdir', 'DAGS_FOLDER/ETL.py', '--cfg-path', '/tmp/tmpgjddja9f']
[2023-11-24T14:37:30.875+0000] {standard_task_runner.py:85} INFO - Job 55: Subtask extract_and_transform_laod
[2023-11-24T14:37:30.918+0000] {task_command.py:416} INFO - Running <TaskInstance: Projet_IDD.extract_and_transform_laod manual__2023-11-24T14:37:27.903328+00:00 [running]> on host efa6202eecdb
[2023-11-24T14:37:31.218+0000] {taskinstance.py:1662} INFO - Exporting env vars: AIRFLOW_CTX_DAG_OWNER='***' AIRFLOW_CTX_DAG_ID='Projet_IDD' AIRFLOW_CTX_TASK_ID='extract_and_transform_laod' AIRFLOW_CTX_EXECUTION_DATE='2023-11-24T14:37:27.903328+00:00' AIRFLOW_CTX_TRY_NUMBER='1' AIRFLOW_CTX_DAG_RUN_ID='manual__2023-11-24T14:37:27.903328+00:00'
[2023-11-24T14:37:31.404+0000] {logging_mixin.py:151} INFO -   Code tranches         age
0             0   tous ages
1             A     0-4 ans
2             B    5-14 ans
3             C   15-44 ans
4             D   45-64 ans
5             E   65-74 ans
6             F  75 et plus
[2023-11-24T14:37:31.468+0000] {logging_mixin.py:151} INFO -         dep date_de_passage  ...  nbre_hospit_corona_h  nbre_hospit_corona_f
0        01      2022-12-26  ...                   1.0                   3.0
1        01      2022-12-26  ...                   NaN                   NaN
2        01      2022-12-26  ...                   NaN                   NaN
3        01      2022-12-26  ...                   NaN                   NaN
4        01      2022-12-26  ...                   NaN                   NaN
...     ...             ...  ...                   ...                   ...
214215  976      2023-10-24  ...                   NaN                   NaN
214216  976      2023-10-24  ...                   NaN                   NaN
214217  976      2023-10-24  ...                   NaN                   NaN
214218  976      2023-10-24  ...                   NaN                   NaN
214219  976      2023-10-24  ...                   NaN                   NaN

[212928 rows x 12 columns]
[2023-11-24T14:37:31.485+0000] {logging_mixin.py:151} INFO - ddddddddddddddd         dep date_de_passage  ... nbre_hospit_corona_h  nbre_hospit_corona_f
0        01      2022-12-26  ...                  1.0                   3.0
1        01      2022-12-26  ...                  NaN                   NaN
2        01      2022-12-26  ...                  NaN                   NaN
3        01      2022-12-26  ...                  NaN                   NaN
4        01      2022-12-26  ...                  NaN                   NaN
...     ...             ...  ...                  ...                   ...
214215  976      2023-10-24  ...                  NaN                   NaN
214216  976      2023-10-24  ...                  NaN                   NaN
214217  976      2023-10-24  ...                  NaN                   NaN
214218  976      2023-10-24  ...                  NaN                   NaN
214219  976      2023-10-24  ...                  NaN                   NaN

[212928 rows x 12 columns]
[2023-11-24T14:37:31.487+0000] {logging_mixin.py:151} INFO - 0       01
1       02
2       03
3       04
4       05
      ... 
96     971
97     972
98     973
99     974
100    976
Name: num_dep, Length: 101, dtype: object
[2023-11-24T14:37:31.495+0000] {base.py:73} INFO - Using connection ID 'postgres_connexion' for task execution.
[2023-11-24T14:37:31.498+0000] {taskinstance.py:1937} ERROR - Task failed with exception
Traceback (most recent call last):
  File "/home/airflow/.local/lib/python3.8/site-packages/sqlalchemy/engine/base.py", line 3371, in _wrap_pool_connect
    return fn()
  File "/home/airflow/.local/lib/python3.8/site-packages/sqlalchemy/pool/base.py", line 327, in connect
    return _ConnectionFairy._checkout(self)
  File "/home/airflow/.local/lib/python3.8/site-packages/sqlalchemy/pool/base.py", line 894, in _checkout
    fairy = _ConnectionRecord.checkout(pool)
  File "/home/airflow/.local/lib/python3.8/site-packages/sqlalchemy/pool/base.py", line 493, in checkout
    rec = pool._do_get()
  File "/home/airflow/.local/lib/python3.8/site-packages/sqlalchemy/pool/impl.py", line 146, in _do_get
    self._dec_overflow()
  File "/home/airflow/.local/lib/python3.8/site-packages/sqlalchemy/util/langhelpers.py", line 70, in __exit__
    compat.raise_(
  File "/home/airflow/.local/lib/python3.8/site-packages/sqlalchemy/util/compat.py", line 211, in raise_
    raise exception
  File "/home/airflow/.local/lib/python3.8/site-packages/sqlalchemy/pool/impl.py", line 143, in _do_get
    return self._create_connection()
  File "/home/airflow/.local/lib/python3.8/site-packages/sqlalchemy/pool/base.py", line 273, in _create_connection
    return _ConnectionRecord(self)
  File "/home/airflow/.local/lib/python3.8/site-packages/sqlalchemy/pool/base.py", line 388, in __init__
    self.__connect()
  File "/home/airflow/.local/lib/python3.8/site-packages/sqlalchemy/pool/base.py", line 691, in __connect
    pool.logger.debug("Error on connect(): %s", e)
  File "/home/airflow/.local/lib/python3.8/site-packages/sqlalchemy/util/langhelpers.py", line 70, in __exit__
    compat.raise_(
  File "/home/airflow/.local/lib/python3.8/site-packages/sqlalchemy/util/compat.py", line 211, in raise_
    raise exception
  File "/home/airflow/.local/lib/python3.8/site-packages/sqlalchemy/pool/base.py", line 686, in __connect
    self.dbapi_connection = connection = pool._invoke_creator(self)
  File "/home/airflow/.local/lib/python3.8/site-packages/sqlalchemy/engine/create.py", line 574, in connect
    return dialect.connect(*cargs, **cparams)
  File "/home/airflow/.local/lib/python3.8/site-packages/sqlalchemy/engine/default.py", line 598, in connect
    return self.dbapi.connect(*cargs, **cparams)
  File "/home/airflow/.local/lib/python3.8/site-packages/psycopg2/__init__.py", line 121, in connect
    dsn = _ext.make_dsn(dsn, **kwargs)
  File "/home/airflow/.local/lib/python3.8/site-packages/psycopg2/extensions.py", line 167, in make_dsn
    parse_dsn(dsn)
psycopg2.ProgrammingError: invalid dsn: invalid connection option "__extra__"


The above exception was the direct cause of the following exception:

Traceback (most recent call last):
  File "/home/airflow/.local/lib/python3.8/site-packages/airflow/operators/python.py", line 192, in execute
    return_value = self.execute_callable()
  File "/home/airflow/.local/lib/python3.8/site-packages/airflow/operators/python.py", line 209, in execute_callable
    return self.python_callable(*self.op_args, **self.op_kwargs)
  File "/opt/airflow/dags/ETL.py", line 57, in extract_and_transform_laod
    df_urgences.to_sql('urgences_hosp', postgres_sql_upload.get_sqlalchemy_engine(), if_exists='replace', chunksize=1000, index=False)
  File "/home/airflow/.local/lib/python3.8/site-packages/pandas/core/generic.py", line 2878, in to_sql
    return sql.to_sql(
  File "/home/airflow/.local/lib/python3.8/site-packages/pandas/io/sql.py", line 768, in to_sql
    with pandasSQL_builder(con, schema=schema, need_transaction=True) as pandas_sql:
  File "/home/airflow/.local/lib/python3.8/site-packages/pandas/io/sql.py", line 832, in pandasSQL_builder
    return SQLDatabase(con, schema, need_transaction)
  File "/home/airflow/.local/lib/python3.8/site-packages/pandas/io/sql.py", line 1539, in __init__
    con = self.exit_stack.enter_context(con.connect())
  File "/home/airflow/.local/lib/python3.8/site-packages/sqlalchemy/engine/base.py", line 3325, in connect
    return self._connection_cls(self, close_with_result=close_with_result)
  File "/home/airflow/.local/lib/python3.8/site-packages/sqlalchemy/engine/base.py", line 96, in __init__
    else engine.raw_connection()
  File "/home/airflow/.local/lib/python3.8/site-packages/sqlalchemy/engine/base.py", line 3404, in raw_connection
    return self._wrap_pool_connect(self.pool.connect, _connection)
  File "/home/airflow/.local/lib/python3.8/site-packages/sqlalchemy/engine/base.py", line 3374, in _wrap_pool_connect
    Connection._handle_dbapi_exception_noconnection(
  File "/home/airflow/.local/lib/python3.8/site-packages/sqlalchemy/engine/base.py", line 2208, in _handle_dbapi_exception_noconnection
    util.raise_(
  File "/home/airflow/.local/lib/python3.8/site-packages/sqlalchemy/util/compat.py", line 211, in raise_
    raise exception
  File "/home/airflow/.local/lib/python3.8/site-packages/sqlalchemy/engine/base.py", line 3371, in _wrap_pool_connect
    return fn()
  File "/home/airflow/.local/lib/python3.8/site-packages/sqlalchemy/pool/base.py", line 327, in connect
    return _ConnectionFairy._checkout(self)
  File "/home/airflow/.local/lib/python3.8/site-packages/sqlalchemy/pool/base.py", line 894, in _checkout
    fairy = _ConnectionRecord.checkout(pool)
  File "/home/airflow/.local/lib/python3.8/site-packages/sqlalchemy/pool/base.py", line 493, in checkout
    rec = pool._do_get()
  File "/home/airflow/.local/lib/python3.8/site-packages/sqlalchemy/pool/impl.py", line 146, in _do_get
    self._dec_overflow()
  File "/home/airflow/.local/lib/python3.8/site-packages/sqlalchemy/util/langhelpers.py", line 70, in __exit__
    compat.raise_(
  File "/home/airflow/.local/lib/python3.8/site-packages/sqlalchemy/util/compat.py", line 211, in raise_
    raise exception
  File "/home/airflow/.local/lib/python3.8/site-packages/sqlalchemy/pool/impl.py", line 143, in _do_get
    return self._create_connection()
  File "/home/airflow/.local/lib/python3.8/site-packages/sqlalchemy/pool/base.py", line 273, in _create_connection
    return _ConnectionRecord(self)
  File "/home/airflow/.local/lib/python3.8/site-packages/sqlalchemy/pool/base.py", line 388, in __init__
    self.__connect()
  File "/home/airflow/.local/lib/python3.8/site-packages/sqlalchemy/pool/base.py", line 691, in __connect
    pool.logger.debug("Error on connect(): %s", e)
  File "/home/airflow/.local/lib/python3.8/site-packages/sqlalchemy/util/langhelpers.py", line 70, in __exit__
    compat.raise_(
  File "/home/airflow/.local/lib/python3.8/site-packages/sqlalchemy/util/compat.py", line 211, in raise_
    raise exception
  File "/home/airflow/.local/lib/python3.8/site-packages/sqlalchemy/pool/base.py", line 686, in __connect
    self.dbapi_connection = connection = pool._invoke_creator(self)
  File "/home/airflow/.local/lib/python3.8/site-packages/sqlalchemy/engine/create.py", line 574, in connect
    return dialect.connect(*cargs, **cparams)
  File "/home/airflow/.local/lib/python3.8/site-packages/sqlalchemy/engine/default.py", line 598, in connect
    return self.dbapi.connect(*cargs, **cparams)
  File "/home/airflow/.local/lib/python3.8/site-packages/psycopg2/__init__.py", line 121, in connect
    dsn = _ext.make_dsn(dsn, **kwargs)
  File "/home/airflow/.local/lib/python3.8/site-packages/psycopg2/extensions.py", line 167, in make_dsn
    parse_dsn(dsn)
sqlalchemy.exc.ProgrammingError: (psycopg2.ProgrammingError) invalid dsn: invalid connection option "__extra__"

(Background on this error at: https://sqlalche.me/e/14/f405)
[2023-11-24T14:37:31.514+0000] {taskinstance.py:1400} INFO - Marking task as FAILED. dag_id=Projet_IDD, task_id=extract_and_transform_laod, execution_date=20231124T143727, start_date=20231124T143730, end_date=20231124T143731
[2023-11-24T14:37:31.525+0000] {standard_task_runner.py:104} ERROR - Failed to execute job 55 for task extract_and_transform_laod ((psycopg2.ProgrammingError) invalid dsn: invalid connection option "__extra__"

(Background on this error at: https://sqlalche.me/e/14/f405); 1721)
[2023-11-24T14:37:31.568+0000] {local_task_job_runner.py:228} INFO - Task exited with return code 1
[2023-11-24T14:37:31.587+0000] {taskinstance.py:2778} INFO - 0 downstream tasks scheduled from follow-on schedule check
