[2023-11-19T19:37:13.662+0000] {taskinstance.py:1159} INFO - Dependencies all met for dep_context=non-requeueable deps ti=<TaskInstance: Projet.Extract manual__2023-11-19T19:37:12.142419+00:00 [queued]>
[2023-11-19T19:37:13.667+0000] {taskinstance.py:1159} INFO - Dependencies all met for dep_context=requeueable deps ti=<TaskInstance: Projet.Extract manual__2023-11-19T19:37:12.142419+00:00 [queued]>
[2023-11-19T19:37:13.667+0000] {taskinstance.py:1361} INFO - Starting attempt 1 of 1
[2023-11-19T19:37:13.673+0000] {taskinstance.py:1382} INFO - Executing <Task(PythonOperator): Extract> on 2023-11-19 19:37:12.142419+00:00
[2023-11-19T19:37:13.680+0000] {standard_task_runner.py:57} INFO - Started process 1271 to run task
[2023-11-19T19:37:13.683+0000] {standard_task_runner.py:84} INFO - Running: ['***', 'tasks', 'run', 'Projet', 'Extract', 'manual__2023-11-19T19:37:12.142419+00:00', '--job-id', '16', '--raw', '--subdir', 'DAGS_FOLDER/dag_sample.py', '--cfg-path', '/tmp/tmp1c0f6a9b']
[2023-11-19T19:37:13.687+0000] {standard_task_runner.py:85} INFO - Job 16: Subtask Extract
[2023-11-19T19:37:13.727+0000] {task_command.py:416} INFO - Running <TaskInstance: Projet.Extract manual__2023-11-19T19:37:12.142419+00:00 [running]> on host 4a664210de45
[2023-11-19T19:37:14.197+0000] {taskinstance.py:1662} INFO - Exporting env vars: AIRFLOW_CTX_DAG_OWNER='***' AIRFLOW_CTX_DAG_ID='Projet' AIRFLOW_CTX_TASK_ID='Extract' AIRFLOW_CTX_EXECUTION_DATE='2023-11-19T19:37:12.142419+00:00' AIRFLOW_CTX_TRY_NUMBER='1' AIRFLOW_CTX_DAG_RUN_ID='manual__2023-11-19T19:37:12.142419+00:00'
[2023-11-19T19:37:14.378+0000] {warnings.py:109} WARNING - /opt/***/dags/dag_sample.py:16: DtypeWarning: Columns (0) have mixed types. Specify dtype option on import or set low_memory=False.
  df_urgences = pd.read_csv(csv_file_path_sos, delimiter=';', dtype={'Code tranches d\'age': str})

[2023-11-19T19:37:14.690+0000] {taskinstance.py:1937} ERROR - Task failed with exception
Traceback (most recent call last):
  File "/home/airflow/.local/lib/python3.8/site-packages/pandas/core/indexes/base.py", line 3653, in get_loc
    return self._engine.get_loc(casted_key)
  File "pandas/_libs/index.pyx", line 147, in pandas._libs.index.IndexEngine.get_loc
  File "pandas/_libs/index.pyx", line 176, in pandas._libs.index.IndexEngine.get_loc
  File "pandas/_libs/hashtable_class_helper.pxi", line 7080, in pandas._libs.hashtable.PyObjectHashTable.get_item
  File "pandas/_libs/hashtable_class_helper.pxi", line 7088, in pandas._libs.hashtable.PyObjectHashTable.get_item
KeyError: 'columns_to_convert'

The above exception was the direct cause of the following exception:

Traceback (most recent call last):
  File "/home/airflow/.local/lib/python3.8/site-packages/airflow/operators/python.py", line 192, in execute
    return_value = self.execute_callable()
  File "/home/airflow/.local/lib/python3.8/site-packages/airflow/operators/python.py", line 209, in execute_callable
    return self.python_callable(*self.op_args, **self.op_kwargs)
  File "/opt/airflow/dags/dag_sample.py", line 41, in data_transform_and_load
    df_urgences['columns_to_convert'] = df_urgences['columns_to_convert'].apply(pd.to_numeric, errors='coerce')
  File "/home/airflow/.local/lib/python3.8/site-packages/pandas/core/frame.py", line 3761, in __getitem__
    indexer = self.columns.get_loc(key)
  File "/home/airflow/.local/lib/python3.8/site-packages/pandas/core/indexes/base.py", line 3655, in get_loc
    raise KeyError(key) from err
KeyError: 'columns_to_convert'
[2023-11-19T19:37:14.700+0000] {taskinstance.py:1400} INFO - Marking task as FAILED. dag_id=Projet, task_id=Extract, execution_date=20231119T193712, start_date=20231119T193713, end_date=20231119T193714
[2023-11-19T19:37:14.708+0000] {standard_task_runner.py:104} ERROR - Failed to execute job 16 for task Extract ('columns_to_convert'; 1271)
[2023-11-19T19:37:14.757+0000] {local_task_job_runner.py:228} INFO - Task exited with return code 1
[2023-11-19T19:37:14.786+0000] {taskinstance.py:2778} INFO - 0 downstream tasks scheduled from follow-on schedule check
