[2023-11-21T17:58:06.816+0000] {taskinstance.py:1159} INFO - Dependencies all met for dep_context=non-requeueable deps ti=<TaskInstance: Projet_IDD.extract_data manual__2023-11-21T17:58:04.790340+00:00 [queued]>
[2023-11-21T17:58:06.825+0000] {taskinstance.py:1159} INFO - Dependencies all met for dep_context=requeueable deps ti=<TaskInstance: Projet_IDD.extract_data manual__2023-11-21T17:58:04.790340+00:00 [queued]>
[2023-11-21T17:58:06.826+0000] {taskinstance.py:1361} INFO - Starting attempt 1 of 1
[2023-11-21T17:58:06.840+0000] {taskinstance.py:1382} INFO - Executing <Task(PythonOperator): extract_data> on 2023-11-21 17:58:04.790340+00:00
[2023-11-21T17:58:06.845+0000] {standard_task_runner.py:57} INFO - Started process 928 to run task
[2023-11-21T17:58:06.848+0000] {standard_task_runner.py:84} INFO - Running: ['***', 'tasks', 'run', 'Projet_IDD', 'extract_data', 'manual__2023-11-21T17:58:04.790340+00:00', '--job-id', '8', '--raw', '--subdir', 'DAGS_FOLDER/ETL.py', '--cfg-path', '/tmp/tmp7x9j1rhb']
[2023-11-21T17:58:06.851+0000] {standard_task_runner.py:85} INFO - Job 8: Subtask extract_data
[2023-11-21T17:58:06.890+0000] {task_command.py:416} INFO - Running <TaskInstance: Projet_IDD.extract_data manual__2023-11-21T17:58:04.790340+00:00 [running]> on host 726cce66553f
[2023-11-21T17:58:07.065+0000] {taskinstance.py:1662} INFO - Exporting env vars: AIRFLOW_CTX_DAG_OWNER='***' AIRFLOW_CTX_DAG_ID='Projet_IDD' AIRFLOW_CTX_TASK_ID='extract_data' AIRFLOW_CTX_EXECUTION_DATE='2023-11-21T17:58:04.790340+00:00' AIRFLOW_CTX_TRY_NUMBER='1' AIRFLOW_CTX_DAG_RUN_ID='manual__2023-11-21T17:58:04.790340+00:00'
[2023-11-21T17:58:07.301+0000] {taskinstance.py:1937} ERROR - Task failed with exception
Traceback (most recent call last):
  File "/home/airflow/.local/lib/python3.8/site-packages/airflow/operators/python.py", line 192, in execute
    return_value = self.execute_callable()
  File "/home/airflow/.local/lib/python3.8/site-packages/airflow/operators/python.py", line 209, in execute_callable
    return self.python_callable(*self.op_args, **self.op_kwargs)
  File "/opt/airflow/dags/ETL.py", line 21, in extract_data
    with open(json_file_path_departements, 'r',encoding="UTF-8") as json_file:
FileNotFoundError: [Errno 2] No such file or directory: '/data/departements-region.json'
[2023-11-21T17:58:07.315+0000] {taskinstance.py:1400} INFO - Marking task as FAILED. dag_id=Projet_IDD, task_id=extract_data, execution_date=20231121T175804, start_date=20231121T175806, end_date=20231121T175807
[2023-11-21T17:58:07.326+0000] {standard_task_runner.py:104} ERROR - Failed to execute job 8 for task extract_data ([Errno 2] No such file or directory: '/data/departements-region.json'; 928)
[2023-11-21T17:58:07.343+0000] {local_task_job_runner.py:228} INFO - Task exited with return code 1
[2023-11-21T17:58:07.360+0000] {taskinstance.py:2778} INFO - 0 downstream tasks scheduled from follow-on schedule check
