[2023-11-21T18:41:31.276+0000] {taskinstance.py:1159} INFO - Dependencies all met for dep_context=non-requeueable deps ti=<TaskInstance: Projet_IDD.load_data manual__2023-11-21T18:41:26.693662+00:00 [queued]>
[2023-11-21T18:41:31.289+0000] {taskinstance.py:1159} INFO - Dependencies all met for dep_context=requeueable deps ti=<TaskInstance: Projet_IDD.load_data manual__2023-11-21T18:41:26.693662+00:00 [queued]>
[2023-11-21T18:41:31.290+0000] {taskinstance.py:1361} INFO - Starting attempt 1 of 1
[2023-11-21T18:41:31.307+0000] {taskinstance.py:1382} INFO - Executing <Task(PythonOperator): load_data> on 2023-11-21 18:41:26.693662+00:00
[2023-11-21T18:41:31.314+0000] {standard_task_runner.py:57} INFO - Started process 1849 to run task
[2023-11-21T18:41:31.318+0000] {standard_task_runner.py:84} INFO - Running: ['***', 'tasks', 'run', 'Projet_IDD', 'load_data', 'manual__2023-11-21T18:41:26.693662+00:00', '--job-id', '46', '--raw', '--subdir', 'DAGS_FOLDER/ETL.py', '--cfg-path', '/tmp/tmp3bj6wgy9']
[2023-11-21T18:41:31.322+0000] {standard_task_runner.py:85} INFO - Job 46: Subtask load_data
[2023-11-21T18:41:31.376+0000] {task_command.py:416} INFO - Running <TaskInstance: Projet_IDD.load_data manual__2023-11-21T18:41:26.693662+00:00 [running]> on host 726cce66553f
[2023-11-21T18:41:31.642+0000] {taskinstance.py:1662} INFO - Exporting env vars: AIRFLOW_CTX_DAG_OWNER='***' AIRFLOW_CTX_DAG_ID='Projet_IDD' AIRFLOW_CTX_TASK_ID='load_data' AIRFLOW_CTX_EXECUTION_DATE='2023-11-21T18:41:26.693662+00:00' AIRFLOW_CTX_TRY_NUMBER='1' AIRFLOW_CTX_DAG_RUN_ID='manual__2023-11-21T18:41:26.693662+00:00'
[2023-11-21T18:41:31.762+0000] {taskinstance.py:1937} ERROR - Task failed with exception
Traceback (most recent call last):
  File "/home/airflow/.local/lib/python3.8/site-packages/airflow/operators/python.py", line 192, in execute
    return_value = self.execute_callable()
  File "/home/airflow/.local/lib/python3.8/site-packages/airflow/operators/python.py", line 209, in execute_callable
    return self.python_callable(*self.op_args, **self.op_kwargs)
  File "/opt/airflow/dags/ETL.py", line 55, in load_data
    df_departements.to_sql('departements', postgres_conn_id="postgres_connexion", if_exists='replace', index=False)
TypeError: to_sql() got an unexpected keyword argument 'postgres_conn_id'
[2023-11-21T18:41:31.780+0000] {taskinstance.py:1400} INFO - Marking task as FAILED. dag_id=Projet_IDD, task_id=load_data, execution_date=20231121T184126, start_date=20231121T184131, end_date=20231121T184131
[2023-11-21T18:41:31.797+0000] {standard_task_runner.py:104} ERROR - Failed to execute job 46 for task load_data (to_sql() got an unexpected keyword argument 'postgres_conn_id'; 1849)
[2023-11-21T18:41:31.814+0000] {local_task_job_runner.py:228} INFO - Task exited with return code 1
[2023-11-21T18:41:31.829+0000] {taskinstance.py:2778} INFO - 0 downstream tasks scheduled from follow-on schedule check
