[2023-11-21T15:26:53.410+0000] {taskinstance.py:1159} INFO - Dependencies all met for dep_context=non-requeueable deps ti=<TaskInstance: Projet_IDD.extract_data manual__2023-11-21T15:26:51.726017+00:00 [queued]>
[2023-11-21T15:26:53.423+0000] {taskinstance.py:1159} INFO - Dependencies all met for dep_context=requeueable deps ti=<TaskInstance: Projet_IDD.extract_data manual__2023-11-21T15:26:51.726017+00:00 [queued]>
[2023-11-21T15:26:53.424+0000] {taskinstance.py:1361} INFO - Starting attempt 1 of 1
[2023-11-21T15:26:53.439+0000] {taskinstance.py:1382} INFO - Executing <Task(PythonOperator): extract_data> on 2023-11-21 15:26:51.726017+00:00
[2023-11-21T15:26:53.448+0000] {standard_task_runner.py:57} INFO - Started process 2526 to run task
[2023-11-21T15:26:53.455+0000] {standard_task_runner.py:84} INFO - Running: ['***', 'tasks', 'run', 'Projet_IDD', 'extract_data', 'manual__2023-11-21T15:26:51.726017+00:00', '--job-id', '17', '--raw', '--subdir', 'DAGS_FOLDER/ETL.py', '--cfg-path', '/tmp/tmp6d31lobo']
[2023-11-21T15:26:53.464+0000] {standard_task_runner.py:85} INFO - Job 17: Subtask extract_data
[2023-11-21T15:26:53.538+0000] {task_command.py:416} INFO - Running <TaskInstance: Projet_IDD.extract_data manual__2023-11-21T15:26:51.726017+00:00 [running]> on host 0fbfe6bcfb8c
[2023-11-21T15:26:54.001+0000] {taskinstance.py:1662} INFO - Exporting env vars: AIRFLOW_CTX_DAG_OWNER='***' AIRFLOW_CTX_DAG_ID='Projet_IDD' AIRFLOW_CTX_TASK_ID='extract_data' AIRFLOW_CTX_EXECUTION_DATE='2023-11-21T15:26:51.726017+00:00' AIRFLOW_CTX_TRY_NUMBER='1' AIRFLOW_CTX_DAG_RUN_ID='manual__2023-11-21T15:26:51.726017+00:00'
[2023-11-21T15:26:54.190+0000] {warnings.py:109} WARNING - /opt/***/dags/ETL.py:14: DtypeWarning: Columns (0) have mixed types. Specify dtype option on import or set low_memory=False.
  df_urgences = pd.read_csv(csv_file_path_sos, delimiter=';')

[2023-11-21T15:26:54.212+0000] {taskinstance.py:1937} ERROR - Task failed with exception
Traceback (most recent call last):
  File "/home/airflow/.local/lib/python3.8/site-packages/airflow/operators/python.py", line 192, in execute
    return_value = self.execute_callable()
  File "/home/airflow/.local/lib/python3.8/site-packages/airflow/operators/python.py", line 209, in execute_callable
    return self.python_callable(*self.op_args, **self.op_kwargs)
  File "/opt/airflow/dags/ETL.py", line 25, in extract_data
    df_urgences = clean_data(df_urgences)
NameError: name 'clean_data' is not defined
[2023-11-21T15:26:54.222+0000] {taskinstance.py:1400} INFO - Marking task as FAILED. dag_id=Projet_IDD, task_id=extract_data, execution_date=20231121T152651, start_date=20231121T152653, end_date=20231121T152654
[2023-11-21T15:26:54.235+0000] {standard_task_runner.py:104} ERROR - Failed to execute job 17 for task extract_data (name 'clean_data' is not defined; 2526)
[2023-11-21T15:26:54.277+0000] {local_task_job_runner.py:228} INFO - Task exited with return code 1
[2023-11-21T15:26:54.295+0000] {taskinstance.py:2778} INFO - 0 downstream tasks scheduled from follow-on schedule check
