[2023-11-21T19:44:43.458+0000] {taskinstance.py:1159} INFO - Dependencies all met for dep_context=non-requeueable deps ti=<TaskInstance: Projet_IDD.load_data manual__2023-11-21T19:44:39.484019+00:00 [queued]>
[2023-11-21T19:44:43.467+0000] {taskinstance.py:1159} INFO - Dependencies all met for dep_context=requeueable deps ti=<TaskInstance: Projet_IDD.load_data manual__2023-11-21T19:44:39.484019+00:00 [queued]>
[2023-11-21T19:44:43.468+0000] {taskinstance.py:1361} INFO - Starting attempt 1 of 1
[2023-11-21T19:44:43.480+0000] {taskinstance.py:1382} INFO - Executing <Task(PythonOperator): load_data> on 2023-11-21 19:44:39.484019+00:00
[2023-11-21T19:44:43.485+0000] {standard_task_runner.py:57} INFO - Started process 2842 to run task
[2023-11-21T19:44:43.488+0000] {standard_task_runner.py:84} INFO - Running: ['***', 'tasks', 'run', 'Projet_IDD', 'load_data', 'manual__2023-11-21T19:44:39.484019+00:00', '--job-id', '84', '--raw', '--subdir', 'DAGS_FOLDER/ETL.py', '--cfg-path', '/tmp/tmpb5qjfkct']
[2023-11-21T19:44:43.492+0000] {standard_task_runner.py:85} INFO - Job 84: Subtask load_data
[2023-11-21T19:44:43.540+0000] {task_command.py:416} INFO - Running <TaskInstance: Projet_IDD.load_data manual__2023-11-21T19:44:39.484019+00:00 [running]> on host 726cce66553f
[2023-11-21T19:44:43.788+0000] {taskinstance.py:1662} INFO - Exporting env vars: AIRFLOW_CTX_DAG_OWNER='***' AIRFLOW_CTX_DAG_ID='Projet_IDD' AIRFLOW_CTX_TASK_ID='load_data' AIRFLOW_CTX_EXECUTION_DATE='2023-11-21T19:44:39.484019+00:00' AIRFLOW_CTX_TRY_NUMBER='1' AIRFLOW_CTX_DAG_RUN_ID='manual__2023-11-21T19:44:39.484019+00:00'
[2023-11-21T19:44:43.923+0000] {base.py:73} INFO - Using connection ID 'postgres_connexion' for task execution.
[2023-11-21T19:44:43.971+0000] {taskinstance.py:1937} ERROR - Task failed with exception
Traceback (most recent call last):
  File "/home/airflow/.local/lib/python3.8/site-packages/sqlalchemy/engine/base.py", line 1890, in _execute_context
    self.dialect.do_executemany(
  File "/home/airflow/.local/lib/python3.8/site-packages/sqlalchemy/dialects/postgresql/psycopg2.py", line 982, in do_executemany
    context._psycopg2_fetched_rows = xtras.execute_values(
  File "/home/airflow/.local/lib/python3.8/site-packages/psycopg2/extras.py", line 1299, in execute_values
    cur.execute(b''.join(parts))
psycopg2.errors.UndefinedColumn: column "num_dep" of relation "passages_corona" does not exist
LINE 1: INSERT INTO passages_corona (num_dep, dep_name, region_name)...
                                     ^


The above exception was the direct cause of the following exception:

Traceback (most recent call last):
  File "/home/airflow/.local/lib/python3.8/site-packages/airflow/operators/python.py", line 192, in execute
    return_value = self.execute_callable()
  File "/home/airflow/.local/lib/python3.8/site-packages/airflow/operators/python.py", line 209, in execute_callable
    return self.python_callable(*self.op_args, **self.op_kwargs)
  File "/opt/airflow/dags/ETL.py", line 55, in load_data
    df_urgences.to_sql('passages_corona', postgres_sql_upload.get_sqlalchemy_engine(), if_exists='append', index=False)
  File "/home/airflow/.local/lib/python3.8/site-packages/pandas/core/generic.py", line 2878, in to_sql
    return sql.to_sql(
  File "/home/airflow/.local/lib/python3.8/site-packages/pandas/io/sql.py", line 769, in to_sql
    return pandas_sql.to_sql(
  File "/home/airflow/.local/lib/python3.8/site-packages/pandas/io/sql.py", line 1920, in to_sql
    total_inserted = sql_engine.insert_records(
  File "/home/airflow/.local/lib/python3.8/site-packages/pandas/io/sql.py", line 1470, in insert_records
    raise err
  File "/home/airflow/.local/lib/python3.8/site-packages/pandas/io/sql.py", line 1461, in insert_records
    return table.insert(chunksize=chunksize, method=method)
  File "/home/airflow/.local/lib/python3.8/site-packages/pandas/io/sql.py", line 1023, in insert
    num_inserted = exec_insert(conn, keys, chunk_iter)
  File "/home/airflow/.local/lib/python3.8/site-packages/pandas/io/sql.py", line 929, in _execute_insert
    result = conn.execute(self.table.insert(), data)
  File "/home/airflow/.local/lib/python3.8/site-packages/sqlalchemy/engine/base.py", line 1385, in execute
    return meth(self, multiparams, params, _EMPTY_EXECUTION_OPTS)
  File "/home/airflow/.local/lib/python3.8/site-packages/sqlalchemy/sql/elements.py", line 334, in _execute_on_connection
    return connection._execute_clauseelement(
  File "/home/airflow/.local/lib/python3.8/site-packages/sqlalchemy/engine/base.py", line 1577, in _execute_clauseelement
    ret = self._execute_context(
  File "/home/airflow/.local/lib/python3.8/site-packages/sqlalchemy/engine/base.py", line 1953, in _execute_context
    self._handle_dbapi_exception(
  File "/home/airflow/.local/lib/python3.8/site-packages/sqlalchemy/engine/base.py", line 2134, in _handle_dbapi_exception
    util.raise_(
  File "/home/airflow/.local/lib/python3.8/site-packages/sqlalchemy/util/compat.py", line 211, in raise_
    raise exception
  File "/home/airflow/.local/lib/python3.8/site-packages/sqlalchemy/engine/base.py", line 1890, in _execute_context
    self.dialect.do_executemany(
  File "/home/airflow/.local/lib/python3.8/site-packages/sqlalchemy/dialects/postgresql/psycopg2.py", line 982, in do_executemany
    context._psycopg2_fetched_rows = xtras.execute_values(
  File "/home/airflow/.local/lib/python3.8/site-packages/psycopg2/extras.py", line 1299, in execute_values
    cur.execute(b''.join(parts))
sqlalchemy.exc.ProgrammingError: (psycopg2.errors.UndefinedColumn) column "num_dep" of relation "passages_corona" does not exist
LINE 1: INSERT INTO passages_corona (num_dep, dep_name, region_name)...
                                     ^

[SQL: INSERT INTO passages_corona (num_dep, dep_name, region_name) VALUES (%(num_dep)s, %(dep_name)s, %(region_name)s)]
[parameters: ({'num_dep': 1, 'dep_name': 'Ain', 'region_name': 'Auvergne-Rhône-Alpes'}, {'num_dep': 2, 'dep_name': 'Aisne', 'region_name': 'Hauts-de-France'}, {'num_dep': 3, 'dep_name': 'Allier', 'region_name': 'Auvergne-Rhône-Alpes'}, {'num_dep': 4, 'dep_name': 'Alpes-de-Haute-Provence', 'region_name': "Provence-Alpes-Côte d'Azur"}, {'num_dep': 5, 'dep_name': 'Hautes-Alpes', 'region_name': "Provence-Alpes-Côte d'Azur"}, {'num_dep': 6, 'dep_name': 'Alpes-Maritimes', 'region_name': "Provence-Alpes-Côte d'Azur"}, {'num_dep': 7, 'dep_name': 'Ardèche', 'region_name': 'Auvergne-Rhône-Alpes'}, {'num_dep': 8, 'dep_name': 'Ardennes', 'region_name': 'Grand Est'}  ... displaying 10 of 101 total bound parameter sets ...  {'num_dep': 974, 'dep_name': 'La Réunion', 'region_name': 'La Réunion'}, {'num_dep': 976, 'dep_name': 'Mayotte', 'region_name': 'Mayotte'})]
(Background on this error at: https://sqlalche.me/e/14/f405)
[2023-11-21T19:44:43.992+0000] {taskinstance.py:1400} INFO - Marking task as FAILED. dag_id=Projet_IDD, task_id=load_data, execution_date=20231121T194439, start_date=20231121T194443, end_date=20231121T194443
[2023-11-21T19:44:44.011+0000] {standard_task_runner.py:104} ERROR - Failed to execute job 84 for task load_data ((psycopg2.errors.UndefinedColumn) column "num_dep" of relation "passages_corona" does not exist
LINE 1: INSERT INTO passages_corona (num_dep, dep_name, region_name)...
                                     ^

[SQL: INSERT INTO passages_corona (num_dep, dep_name, region_name) VALUES (%(num_dep)s, %(dep_name)s, %(region_name)s)]
[parameters: ({'num_dep': 1, 'dep_name': 'Ain', 'region_name': 'Auvergne-Rhône-Alpes'}, {'num_dep': 2, 'dep_name': 'Aisne', 'region_name': 'Hauts-de-France'}, {'num_dep': 3, 'dep_name': 'Allier', 'region_name': 'Auvergne-Rhône-Alpes'}, {'num_dep': 4, 'dep_name': 'Alpes-de-Haute-Provence', 'region_name': "Provence-Alpes-Côte d'Azur"}, {'num_dep': 5, 'dep_name': 'Hautes-Alpes', 'region_name': "Provence-Alpes-Côte d'Azur"}, {'num_dep': 6, 'dep_name': 'Alpes-Maritimes', 'region_name': "Provence-Alpes-Côte d'Azur"}, {'num_dep': 7, 'dep_name': 'Ardèche', 'region_name': 'Auvergne-Rhône-Alpes'}, {'num_dep': 8, 'dep_name': 'Ardennes', 'region_name': 'Grand Est'}  ... displaying 10 of 101 total bound parameter sets ...  {'num_dep': 974, 'dep_name': 'La Réunion', 'region_name': 'La Réunion'}, {'num_dep': 976, 'dep_name': 'Mayotte', 'region_name': 'Mayotte'})]
(Background on this error at: https://sqlalche.me/e/14/f405); 2842)
[2023-11-21T19:44:44.063+0000] {local_task_job_runner.py:228} INFO - Task exited with return code 1
[2023-11-21T19:44:44.083+0000] {taskinstance.py:2778} INFO - 0 downstream tasks scheduled from follow-on schedule check
